<sdf version='1.7'>
  <world name='grid3'>
    <model name='stage2'>
      <link name='ridges'>
        <self_collide>0</self_collide>
        <pose>0 0 0 0 0 -1.57</pose>
        <inertial>
          <pose>0 0 0 0 -0 0</pose>
          <mass>10</mass>
          <inertia>
            <ixx>0.83</ixx>
            <ixy>-0</ixy>
            <ixz>-0</ixz>
            <iyy>0.83</iyy>
            <iyz>-0</iyz>
            <izz>0.83</izz>
          </inertia>
        </inertial>
        <collision name='stage'>
          <geometry>
            <box>
              <size>4.8768 4.8768 0.1</size>
            </box>
          </geometry>
          <surface>
            <friction>
              <ode>
                <mu>1</mu>
                <mu2>1</mu2>
              </ode>
              <torsional>
                <ode/>
              </torsional>
            </friction>
            <contact>
              <ode/>
            </contact>
            <bounce/>
          </surface>
          <max_contacts>10</max_contacts>
        </collision>
        <visual name='stage'>
          <geometry>
            <box>
              <size>4.8768 4.8768 0.1</size>
            </box>
          </geometry>
          <material>
            <script>
              <uri>model://planeStage2/materials/scripts/</uri>
              <uri>model://planeStage2/materials/textures/</uri>
              <name>planeStage2/Image</name>
            </script>
          </material>
        </visual>
        <enable_wind>0</enable_wind>
        <kinematic>0</kinematic>
      </link>
      <static>1</static>
      <pose>1.2192 1.2192 -0.045 0 -0 1.5708</pose>
    </model>
    <light name='sun' type='directional'>
      <cast_shadows>1</cast_shadows>
      <pose>0 0 10 0 -0 0</pose>
      <diffuse>0.8 0.8 0.8 1</diffuse>
      <specular>0.2 0.2 0.2 1</specular>
      <attenuation>
        <range>1000</range>
        <constant>0.9</constant>
        <linear>0.01</linear>
        <quadratic>0.001</quadratic>
      </attenuation>
      <direction>-0.5 0.1 -0.9</direction>
      <spot>
        <inner_angle>0</inner_angle>
        <outer_angle>0</outer_angle>
        <falloff>0</falloff>
      </spot>
    </light>
    <gravity>0 0 -9.8</gravity>
    <magnetic_field>6e-06 2.3e-05 -4.2e-05</magnetic_field>
    <atmosphere type='adiabatic'/>
    <physics type='ode'>
      <max_step_size>0.001</max_step_size>
      <real_time_factor>1</real_time_factor>
      <real_time_update_rate>1000</real_time_update_rate>
    </physics>
    <scene>
      <ambient>0.4 0.4 0.4 1</ambient>
      <background>0.7 0.7 0.7 1</background>
      <shadows>1</shadows>
    </scene>
    <wind/>
    <spherical_coordinates>
      <surface_model>EARTH_WGS84</surface_model>
      <latitude_deg>0</latitude_deg>
      <longitude_deg>0</longitude_deg>
      <elevation>0</elevation>
      <heading_deg>0</heading_deg>
    </spherical_coordinates>
    <model name='myrobot1'>
      <link name='chassis1'>
        <inertial>
          <pose>0 0 0.1 0 -0 0</pose>
          <mass>10</mass>
          <inertia>
            <ixx>0.5</ixx>
            <ixy>0</ixy>
            <ixz>0</ixz>
            <iyy>1</iyy>
            <iyz>0</iyz>
            <izz>0.1</izz>
          </inertia>
        </inertial>
        <collision name='chassis1_fixed_joint_lump__collision_collision'>
          <pose>0 0 0 0 -0 0</pose>
          <geometry>
            <box>
              <size>0.1016 0.1016 0.02</size>
            </box>
          </geometry>
          <surface>
            <contact>
              <ode/>
            </contact>
            <bounce/>
            <friction>
              <torsional>
                <ode/>
              </torsional>
              <ode/>
            </friction>
          </surface>
          <max_contacts>10</max_contacts>
        </collision>
        <visual name='chassis1_visual_visual'>
          <pose>0 0 0 0 -0 0</pose>
          <geometry>
            <box>
              <size>0.1016 0.1016 0.02</size>
            </box>
          </geometry>
          <material>
            <script>
              <name>robot1/Image</name>
              <uri>file://media/materials/scripts/gazebo.material</uri>
            </script>
          </material>
        </visual>
        <gravity>1</gravity>
        <velocity_decay/>
        <self_collide>0</self_collide>
        <enable_wind>0</enable_wind>
        <kinematic>0</kinematic>
      </link>
      <joint name='left_back_wheel_hinge' type='revolute'>
        <pose relative_to='chassis1'>-0.0381 0.0584 0 0 -0 0</pose>
        <parent>chassis1</parent>
        <child>left_back_wheel</child>
        <axis>
          <xyz>0 1 0</xyz>
          <limit>
            <lower>-1e+16</lower>
            <upper>1e+16</upper>
          </limit>
          <dynamics>
            <spring_reference>0</spring_reference>
            <spring_stiffness>0</spring_stiffness>
          </dynamics>
        </axis>
      </joint>
      <link name='left_back_wheel'>
        <pose relative_to='left_back_wheel_hinge'>0 0 0 0 -0 0</pose>
        <inertial>
          <pose>0 0 0 -0 1.5707 1.5707</pose>
          <mass>10</mass>
          <inertia>
            <ixx>1</ixx>
            <ixy>0</ixy>
            <ixz>0</ixz>
            <iyy>1</iyy>
            <iyz>0</iyz>
            <izz>1</izz>
          </inertia>
        </inertial>
        <collision name='left_back_wheel_fixed_joint_lump__collision_collision'>
          <pose>0 0 0 1.57089 1.57079 -3.14159</pose>
          <geometry>
            <cylinder>
              <length>0.0127</length>
              <radius>0.02</radius>
            </cylinder>
          </geometry>
          <surface>
            <contact>
              <ode/>
            </contact>
            <bounce/>
            <friction>
              <torsional>
                <ode/>
              </torsional>
              <ode/>
            </friction>
          </surface>
          <max_contacts>10</max_contacts>
        </collision>
        <visual name='left_back_wheel_visual_visual'>
          <pose>0 0 0 1.57089 1.57079 -3.14159</pose>
          <geometry>
            <cylinder>
              <length>0.0127</length>
              <radius>0.02</radius>
            </cylinder>
          </geometry>
          <material>
            <script>
              <name>Gazebo/Black</name>
              <uri>file://media/materials/scripts/gazebo.material</uri>
            </script>
          </material>
        </visual>
        <gravity>1</gravity>
        <velocity_decay/>
        <self_collide>0</self_collide>
        <enable_wind>0</enable_wind>
        <kinematic>0</kinematic>
      </link>
      <joint name='left_front_wheel_hinge' type='revolute'>
        <pose relative_to='chassis1'>0.0381 0.0584 0 0 -0 0</pose>
        <parent>chassis1</parent>
        <child>left_front_wheel</child>
        <axis>
          <xyz>0 1 0</xyz>
          <limit>
            <lower>-1e+16</lower>
            <upper>1e+16</upper>
          </limit>
          <dynamics>
            <spring_reference>0</spring_reference>
            <spring_stiffness>0</spring_stiffness>
          </dynamics>
        </axis>
      </joint>
      <link name='left_front_wheel'>
        <pose relative_to='left_front_wheel_hinge'>0 0 0 0 -0 0</pose>
        <inertial>
          <pose>0 0 0 -0 1.5707 1.5707</pose>
          <mass>10</mass>
          <inertia>
            <ixx>1</ixx>
            <ixy>0</ixy>
            <ixz>0</ixz>
            <iyy>1</iyy>
            <iyz>0</iyz>
            <izz>1</izz>
          </inertia>
        </inertial>
        <collision name='left_front_wheel_fixed_joint_lump__collision_collision'>
          <pose>0 0 0 1.57089 1.57079 -3.14159</pose>
          <geometry>
            <cylinder>
              <length>0.0127</length>
              <radius>0.02</radius>
            </cylinder>
          </geometry>
          <surface>
            <contact>
              <ode/>
            </contact>
            <bounce/>
            <friction>
              <torsional>
                <ode/>
              </torsional>
              <ode/>
            </friction>
          </surface>
          <max_contacts>10</max_contacts>
        </collision>
        <visual name='left_front_wheel_visual_visual'>
          <pose>0 0 0 1.57089 1.57079 -3.14159</pose>
          <geometry>
            <cylinder>
              <length>0.0127</length>
              <radius>0.02</radius>
            </cylinder>
          </geometry>
          <material>
            <script>
              <name>Gazebo/Black</name>
              <uri>file://media/materials/scripts/gazebo.material</uri>
            </script>
          </material>
        </visual>
        <gravity>1</gravity>
        <velocity_decay/>
        <self_collide>0</self_collide>
        <enable_wind>0</enable_wind>
        <kinematic>0</kinematic>
      </link>
      <joint name='right_back_wheel_hinge' type='revolute'>
        <pose relative_to='chassis1'>-0.0381 -0.0584 0 0 -0 0</pose>
        <parent>chassis1</parent>
        <child>right_back_wheel</child>
        <axis>
          <xyz>0 1 0</xyz>
          <limit>
            <lower>-1e+16</lower>
            <upper>1e+16</upper>
          </limit>
          <dynamics>
            <spring_reference>0</spring_reference>
            <spring_stiffness>0</spring_stiffness>
          </dynamics>
        </axis>
      </joint>
      <link name='right_back_wheel'>
        <pose relative_to='right_back_wheel_hinge'>0 0 0 0 -0 0</pose>
        <inertial>
          <pose>0 0 0 -0 1.5707 1.5707</pose>
          <mass>10</mass>
          <inertia>
            <ixx>1</ixx>
            <ixy>0</ixy>
            <ixz>0</ixz>
            <iyy>1</iyy>
            <iyz>0</iyz>
            <izz>1</izz>
          </inertia>
        </inertial>
        <collision name='right_back_wheel_fixed_joint_lump__collision_collision'>
          <pose>0 0 0 1.57089 1.57079 -3.14159</pose>
          <geometry>
            <cylinder>
              <length>0.0127</length>
              <radius>0.02</radius>
            </cylinder>
          </geometry>
          <surface>
            <contact>
              <ode/>
            </contact>
            <bounce/>
            <friction>
              <torsional>
                <ode/>
              </torsional>
              <ode/>
            </friction>
          </surface>
          <max_contacts>10</max_contacts>
        </collision>
        <visual name='right_back_wheel_visual_visual'>
          <pose>0 0 0 1.57089 1.57079 -3.14159</pose>
          <geometry>
            <cylinder>
              <length>0.0127</length>
              <radius>0.02</radius>
            </cylinder>
          </geometry>
          <material>
            <script>
              <name>Gazebo/Black</name>
              <uri>file://media/materials/scripts/gazebo.material</uri>
            </script>
          </material>
        </visual>
        <gravity>1</gravity>
        <velocity_decay/>
        <self_collide>0</self_collide>
        <enable_wind>0</enable_wind>
        <kinematic>0</kinematic>
      </link>
      <joint name='right_front_wheel_hinge' type='revolute'>
        <pose relative_to='chassis1'>0.0381 -0.0584 0 0 -0 0</pose>
        <parent>chassis1</parent>
        <child>right_front_wheel</child>
        <axis>
          <xyz>0 1 0</xyz>
          <limit>
            <lower>-1e+16</lower>
            <upper>1e+16</upper>
          </limit>
          <dynamics>
            <spring_reference>0</spring_reference>
            <spring_stiffness>0</spring_stiffness>
          </dynamics>
        </axis>
      </joint>
      <link name='right_front_wheel'>
        <pose relative_to='right_front_wheel_hinge'>0 0 0 0 -0 0</pose>
        <inertial>
          <pose>0 0 0 -0 1.5707 1.5707</pose>
          <mass>10</mass>
          <inertia>
            <ixx>1</ixx>
            <ixy>0</ixy>
            <ixz>0</ixz>
            <iyy>1</iyy>
            <iyz>0</iyz>
            <izz>1</izz>
          </inertia>
        </inertial>
        <collision name='right_front_wheel_fixed_joint_lump__collision_collision'>
          <pose>0 0 0 1.57089 1.57079 -3.14159</pose>
          <geometry>
            <cylinder>
              <length>0.0127</length>
              <radius>0.02</radius>
            </cylinder>
          </geometry>
          <surface>
            <contact>
              <ode/>
            </contact>
            <bounce/>
            <friction>
              <torsional>
                <ode/>
              </torsional>
              <ode/>
            </friction>
          </surface>
          <max_contacts>10</max_contacts>
        </collision>
        <visual name='right_front_wheel_visual_visual'>
          <pose>0 0 0 1.57089 1.57079 -3.14159</pose>
          <geometry>
            <cylinder>
              <length>0.0127</length>
              <radius>0.02</radius>
            </cylinder>
          </geometry>
          <material>
            <script>
              <name>Gazebo/Black</name>
              <uri>file://media/materials/scripts/gazebo.material</uri>
            </script>
          </material>
        </visual>
        <gravity>1</gravity>
        <velocity_decay/>
        <self_collide>0</self_collide>
        <enable_wind>0</enable_wind>
        <kinematic>0</kinematic>
      </link>
      <static>0</static>
      <plugin name='differential_drive_controller' filename='libgazebo_ros_diff_drive.so'>
        <legacyMode>0</legacyMode>
        <alwaysOn>1</alwaysOn>
        <updateRate>20</updateRate>
        <leftJoint>left_back_wheel_hinge</leftJoint>
        <rightJoint>right_back_wheel_hinge</rightJoint>
        <wheelSeparation>0.1608</wheelSeparation>
        <wheelDiameter>0.1</wheelDiameter>
        <wheelTorque>5</wheelTorque>
        <commandTopic>robot1/cmd_vel</commandTopic>
        <odometryTopic>robot1/odom</odometryTopic>
        <odometryFrame>grid/odom</odometryFrame>
        <robotBaseFrame>chassis1</robotBaseFrame>
        <robotNamespace>/</robotNamespace>
      </plugin>
      <pose>0.9889 0.078812 0.05 0 -0 1.5708</pose>
    </model>
    <model name='myrobot3'>
      <link name='chassis3'>
        <inertial>
          <pose>0 0 0.1 0 -0 0</pose>
          <mass>10</mass>
          <inertia>
            <ixx>0.5</ixx>
            <ixy>0</ixy>
            <ixz>0</ixz>
            <iyy>1</iyy>
            <iyz>0</iyz>
            <izz>0.1</izz>
          </inertia>
        </inertial>
        <collision name='chassis3_fixed_joint_lump__collision_collision'>
          <pose>0 0 0 0 -0 0</pose>
          <geometry>
            <box>
              <size>0.1016 0.1016 0.02</size>
            </box>
          </geometry>
          <surface>
            <contact>
              <ode/>
            </contact>
            <bounce/>
            <friction>
              <torsional>
                <ode/>
              </torsional>
              <ode/>
            </friction>
          </surface>
          <max_contacts>10</max_contacts>
        </collision>
        <visual name='chassis3_visual_visual'>
          <pose>0 0 0 0 -0 0</pose>
          <geometry>
            <box>
              <size>0.1016 0.1016 0.02</size>
            </box>
          </geometry>
          <material>
            <script>
              <name>robot3/Image</name>
              <uri>file://media/materials/scripts/gazebo.material</uri>
            </script>
          </material>
        </visual>
        <gravity>1</gravity>
        <velocity_decay/>
        <self_collide>0</self_collide>
        <enable_wind>0</enable_wind>
        <kinematic>0</kinematic>
      </link>
      <joint name='left_back_wheel_hinge' type='revolute'>
        <pose relative_to='chassis3'>-0.0381 0.0584 0 0 -0 0</pose>
        <parent>chassis3</parent>
        <child>left_back_wheel</child>
        <axis>
          <xyz>0 1 0</xyz>
          <limit>
            <lower>-1e+16</lower>
            <upper>1e+16</upper>
          </limit>
          <dynamics>
            <spring_reference>0</spring_reference>
            <spring_stiffness>0</spring_stiffness>
          </dynamics>
        </axis>
      </joint>
      <link name='left_back_wheel'>
        <pose relative_to='left_back_wheel_hinge'>0 0 0 0 -0 0</pose>
        <inertial>
          <pose>0 0 0 -0 1.5707 1.5707</pose>
          <mass>5</mass>
          <inertia>
            <ixx>1</ixx>
            <ixy>0</ixy>
            <ixz>0</ixz>
            <iyy>1</iyy>
            <iyz>0</iyz>
            <izz>1</izz>
          </inertia>
        </inertial>
        <collision name='left_back_wheel_fixed_joint_lump__collision_collision'>
          <pose>0 0 0 1.57089 1.57079 -3.14159</pose>
          <geometry>
            <cylinder>
              <length>0.0127</length>
              <radius>0.02</radius>
            </cylinder>
          </geometry>
          <surface>
            <contact>
              <ode/>
            </contact>
            <bounce/>
            <friction>
              <torsional>
                <ode/>
              </torsional>
              <ode/>
            </friction>
          </surface>
          <max_contacts>10</max_contacts>
        </collision>
        <visual name='left_back_wheel_visual_visual'>
          <pose>0 0 0 1.57089 1.57079 -3.14159</pose>
          <geometry>
            <cylinder>
              <length>0.0127</length>
              <radius>0.02</radius>
            </cylinder>
          </geometry>
          <material>
            <script>
              <name>Gazebo/Black</name>
              <uri>file://media/materials/scripts/gazebo.material</uri>
            </script>
          </material>
        </visual>
        <gravity>1</gravity>
        <velocity_decay/>
        <self_collide>0</self_collide>
        <enable_wind>0</enable_wind>
        <kinematic>0</kinematic>
      </link>
      <joint name='left_front_wheel_hinge' type='revolute'>
        <pose relative_to='chassis3'>0.0381 0.0584 0 0 -0 0</pose>
        <parent>chassis3</parent>
        <child>left_front_wheel</child>
        <axis>
          <xyz>0 1 0</xyz>
          <limit>
            <lower>-1e+16</lower>
            <upper>1e+16</upper>
          </limit>
          <dynamics>
            <spring_reference>0</spring_reference>
            <spring_stiffness>0</spring_stiffness>
          </dynamics>
        </axis>
      </joint>
      <link name='left_front_wheel'>
        <pose relative_to='left_front_wheel_hinge'>0 0 0 0 -0 0</pose>
        <inertial>
          <pose>0 0 0 -0 1.5707 1.5707</pose>
          <mass>5</mass>
          <inertia>
            <ixx>1</ixx>
            <ixy>0</ixy>
            <ixz>0</ixz>
            <iyy>1</iyy>
            <iyz>0</iyz>
            <izz>1</izz>
          </inertia>
        </inertial>
        <collision name='left_front_wheel_fixed_joint_lump__collision_collision'>
          <pose>0 0 0 1.57089 1.57079 -3.14159</pose>
          <geometry>
            <cylinder>
              <length>0.0127</length>
              <radius>0.02</radius>
            </cylinder>
          </geometry>
          <surface>
            <contact>
              <ode/>
            </contact>
            <bounce/>
            <friction>
              <torsional>
                <ode/>
              </torsional>
              <ode/>
            </friction>
          </surface>
          <max_contacts>10</max_contacts>
        </collision>
        <visual name='left_front_wheel_visual_visual'>
          <pose>0 0 0 1.57089 1.57079 -3.14159</pose>
          <geometry>
            <cylinder>
              <length>0.0127</length>
              <radius>0.02</radius>
            </cylinder>
          </geometry>
          <material>
            <script>
              <name>Gazebo/Black</name>
              <uri>file://media/materials/scripts/gazebo.material</uri>
            </script>
          </material>
        </visual>
        <gravity>1</gravity>
        <velocity_decay/>
        <self_collide>0</self_collide>
        <enable_wind>0</enable_wind>
        <kinematic>0</kinematic>
      </link>
      <joint name='right_back_wheel_hinge' type='revolute'>
        <pose relative_to='chassis3'>-0.0381 -0.0584 0 0 -0 0</pose>
        <parent>chassis3</parent>
        <child>right_back_wheel</child>
        <axis>
          <xyz>0 1 0</xyz>
          <limit>
            <lower>-1e+16</lower>
            <upper>1e+16</upper>
          </limit>
          <dynamics>
            <spring_reference>0</spring_reference>
            <spring_stiffness>0</spring_stiffness>
          </dynamics>
        </axis>
      </joint>
      <link name='right_back_wheel'>
        <pose relative_to='right_back_wheel_hinge'>0 0 0 0 -0 0</pose>
        <inertial>
          <pose>0 0 0 -0 1.5707 1.5707</pose>
          <mass>5</mass>
          <inertia>
            <ixx>1</ixx>
            <ixy>0</ixy>
            <ixz>0</ixz>
            <iyy>1</iyy>
            <iyz>0</iyz>
            <izz>1</izz>
          </inertia>
        </inertial>
        <collision name='right_back_wheel_fixed_joint_lump__collision_collision'>
          <pose>0 0 0 1.57089 1.57079 -3.14159</pose>
          <geometry>
            <cylinder>
              <length>0.0127</length>
              <radius>0.02</radius>
            </cylinder>
          </geometry>
          <surface>
            <contact>
              <ode/>
            </contact>
            <bounce/>
            <friction>
              <torsional>
                <ode/>
              </torsional>
              <ode/>
            </friction>
          </surface>
          <max_contacts>10</max_contacts>
        </collision>
        <visual name='right_back_wheel_visual_visual'>
          <pose>0 0 0 1.57089 1.57079 -3.14159</pose>
          <geometry>
            <cylinder>
              <length>0.0127</length>
              <radius>0.02</radius>
            </cylinder>
          </geometry>
          <material>
            <script>
              <name>Gazebo/Black</name>
              <uri>file://media/materials/scripts/gazebo.material</uri>
            </script>
          </material>
        </visual>
        <gravity>1</gravity>
        <velocity_decay/>
        <self_collide>0</self_collide>
        <enable_wind>0</enable_wind>
        <kinematic>0</kinematic>
      </link>
      <joint name='right_front_wheel_hinge' type='revolute'>
        <pose relative_to='chassis3'>0.0381 -0.0584 0 0 -0 0</pose>
        <parent>chassis3</parent>
        <child>right_front_wheel</child>
        <axis>
          <xyz>0 1 0</xyz>
          <limit>
            <lower>-1e+16</lower>
            <upper>1e+16</upper>
          </limit>
          <dynamics>
            <spring_reference>0</spring_reference>
            <spring_stiffness>0</spring_stiffness>
          </dynamics>
        </axis>
      </joint>
      <link name='right_front_wheel'>
        <pose relative_to='right_front_wheel_hinge'>0 0 0 0 -0 0</pose>
        <inertial>
          <pose>0 0 0 -0 1.5707 1.5707</pose>
          <mass>5</mass>
          <inertia>
            <ixx>1</ixx>
            <ixy>0</ixy>
            <ixz>0</ixz>
            <iyy>1</iyy>
            <iyz>0</iyz>
            <izz>1</izz>
          </inertia>
        </inertial>
        <collision name='right_front_wheel_fixed_joint_lump__collision_collision'>
          <pose>0 0 0 1.57089 1.57079 -3.14159</pose>
          <geometry>
            <cylinder>
              <length>0.0127</length>
              <radius>0.02</radius>
            </cylinder>
          </geometry>
          <surface>
            <contact>
              <ode/>
            </contact>
            <bounce/>
            <friction>
              <torsional>
                <ode/>
              </torsional>
              <ode/>
            </friction>
          </surface>
          <max_contacts>10</max_contacts>
        </collision>
        <visual name='right_front_wheel_visual_visual'>
          <pose>0 0 0 1.57089 1.57079 -3.14159</pose>
          <geometry>
            <cylinder>
              <length>0.0127</length>
              <radius>0.02</radius>
            </cylinder>
          </geometry>
          <material>
            <script>
              <name>Gazebo/Black</name>
              <uri>file://media/materials/scripts/gazebo.material</uri>
            </script>
          </material>
        </visual>
        <gravity>1</gravity>
        <velocity_decay/>
        <self_collide>0</self_collide>
        <enable_wind>0</enable_wind>
        <kinematic>0</kinematic>
      </link>
      <static>0</static>
      <plugin name='differential_drive_controller' filename='libgazebo_ros_diff_drive.so'>
        <legacyMode>0</legacyMode>
        <alwaysOn>1</alwaysOn>
        <updateRate>20</updateRate>
        <leftJoint>left_back_wheel_hinge</leftJoint>
        <rightJoint>right_back_wheel_hinge</rightJoint>
        <wheelSeparation>0.4</wheelSeparation>
        <wheelDiameter>0.1</wheelDiameter>
        <wheelTorque>5</wheelTorque>
        <commandTopic>robot3/cmd_vel</commandTopic>
        <odometryTopic>robot3/odom</odometryTopic>
        <odometryFrame>grid/odom</odometryFrame>
        <robotBaseFrame>chassis3</robotBaseFrame>
        <robotNamespace>/</robotNamespace>
      </plugin>
      <pose>0.9889 2.35959 0.05 0 0 -1.5708</pose>
    </model>
    <model name='myrobot2'>
      <link name='chassis2'>
        <inertial>
          <pose>0 0 0.1 0 -0 0</pose>
          <mass>10</mass>
          <inertia>
            <ixx>0.5</ixx>
            <ixy>0</ixy>
            <ixz>0</ixz>
            <iyy>1</iyy>
            <iyz>0</iyz>
            <izz>0.1</izz>
          </inertia>
        </inertial>
        <collision name='chassis2_fixed_joint_lump__collision_collision'>
          <pose>0 0 0 0 -0 0</pose>
          <geometry>
            <box>
              <size>0.1016 0.1016 0.02</size>
            </box>
          </geometry>
          <surface>
            <contact>
              <ode/>
            </contact>
            <bounce/>
            <friction>
              <torsional>
                <ode/>
              </torsional>
              <ode/>
            </friction>
          </surface>
          <max_contacts>10</max_contacts>
        </collision>
        <visual name='chassis2_visual_visual'>
          <pose>0 0 0 0 -0 0</pose>
          <geometry>
            <box>
              <size>0.1016 0.1016 0.02</size>
            </box>
          </geometry>
          <material>
            <script>
              <name>robot2/Image</name>
              <uri>file://media/materials/scripts/gazebo.material</uri>
            </script>
          </material>
        </visual>
        <gravity>1</gravity>
        <velocity_decay/>
        <self_collide>0</self_collide>
        <enable_wind>0</enable_wind>
        <kinematic>0</kinematic>
      </link>
      <joint name='left_back_wheel_hinge' type='revolute'>
        <pose relative_to='chassis2'>-0.0381 0.0584 0 0 -0 0</pose>
        <parent>chassis2</parent>
        <child>left_back_wheel</child>
        <axis>
          <xyz>0 1 0</xyz>
          <limit>
            <lower>-1e+16</lower>
            <upper>1e+16</upper>
          </limit>
          <dynamics>
            <spring_reference>0</spring_reference>
            <spring_stiffness>0</spring_stiffness>
          </dynamics>
        </axis>
      </joint>
      <link name='left_back_wheel'>
        <pose relative_to='left_back_wheel_hinge'>0 0 0 0 -0 0</pose>
        <inertial>
          <pose>0 0 0 -0 1.5707 1.5707</pose>
          <mass>10</mass>
          <inertia>
            <ixx>1</ixx>
            <ixy>0</ixy>
            <ixz>0</ixz>
            <iyy>1</iyy>
            <iyz>0</iyz>
            <izz>1</izz>
          </inertia>
        </inertial>
        <collision name='left_back_wheel_fixed_joint_lump__collision_collision'>
          <pose>0 0 0 1.57089 1.57079 -3.14159</pose>
          <geometry>
            <cylinder>
              <length>0.0127</length>
              <radius>0.02</radius>
            </cylinder>
          </geometry>
          <surface>
            <contact>
              <ode/>
            </contact>
            <bounce/>
            <friction>
              <torsional>
                <ode/>
              </torsional>
              <ode/>
            </friction>
          </surface>
          <max_contacts>10</max_contacts>
        </collision>
        <visual name='left_back_wheel_visual_visual'>
          <pose>0 0 0 1.57089 1.57079 -3.14159</pose>
          <geometry>
            <cylinder>
              <length>0.0127</length>
              <radius>0.02</radius>
            </cylinder>
          </geometry>
          <material>
            <script>
              <name>Gazebo/Black</name>
              <uri>file://media/materials/scripts/gazebo.material</uri>
            </script>
          </material>
        </visual>
        <gravity>1</gravity>
        <velocity_decay/>
        <self_collide>0</self_collide>
        <enable_wind>0</enable_wind>
        <kinematic>0</kinematic>
      </link>
      <joint name='left_front_wheel_hinge' type='revolute'>
        <pose relative_to='chassis2'>0.0381 0.0584 0 0 -0 0</pose>
        <parent>chassis2</parent>
        <child>left_front_wheel</child>
        <axis>
          <xyz>0 1 0</xyz>
          <limit>
            <lower>-1e+16</lower>
            <upper>1e+16</upper>
          </limit>
          <dynamics>
            <spring_reference>0</spring_reference>
            <spring_stiffness>0</spring_stiffness>
          </dynamics>
        </axis>
      </joint>
      <link name='left_front_wheel'>
        <pose relative_to='left_front_wheel_hinge'>0 0 0 0 -0 0</pose>
        <inertial>
          <pose>0 0 0 -0 1.5707 1.5707</pose>
          <mass>10</mass>
          <inertia>
            <ixx>1</ixx>
            <ixy>0</ixy>
            <ixz>0</ixz>
            <iyy>1</iyy>
            <iyz>0</iyz>
            <izz>1</izz>
          </inertia>
        </inertial>
        <collision name='left_front_wheel_fixed_joint_lump__collision_collision'>
          <pose>0 0 0 1.57089 1.57079 -3.14159</pose>
          <geometry>
            <cylinder>
              <length>0.0127</length>
              <radius>0.02</radius>
            </cylinder>
          </geometry>
          <surface>
            <contact>
              <ode/>
            </contact>
            <bounce/>
            <friction>
              <torsional>
                <ode/>
              </torsional>
              <ode/>
            </friction>
          </surface>
          <max_contacts>10</max_contacts>
        </collision>
        <visual name='left_front_wheel_visual_visual'>
          <pose>0 0 0 1.57089 1.57079 -3.14159</pose>
          <geometry>
            <cylinder>
              <length>0.0127</length>
              <radius>0.02</radius>
            </cylinder>
          </geometry>
          <material>
            <script>
              <name>Gazebo/Black</name>
              <uri>file://media/materials/scripts/gazebo.material</uri>
            </script>
          </material>
        </visual>
        <gravity>1</gravity>
        <velocity_decay/>
        <self_collide>0</self_collide>
        <enable_wind>0</enable_wind>
        <kinematic>0</kinematic>
      </link>
      <joint name='right_back_wheel_hinge' type='revolute'>
        <pose relative_to='chassis2'>-0.0381 -0.0584 0 0 -0 0</pose>
        <parent>chassis2</parent>
        <child>right_back_wheel</child>
        <axis>
          <xyz>0 1 0</xyz>
          <limit>
            <lower>-1e+16</lower>
            <upper>1e+16</upper>
          </limit>
          <dynamics>
            <spring_reference>0</spring_reference>
            <spring_stiffness>0</spring_stiffness>
          </dynamics>
        </axis>
      </joint>
      <link name='right_back_wheel'>
        <pose relative_to='right_back_wheel_hinge'>0 0 0 0 -0 0</pose>
        <inertial>
          <pose>0 0 0 -0 1.5707 1.5707</pose>
          <mass>10</mass>
          <inertia>
            <ixx>1</ixx>
            <ixy>0</ixy>
            <ixz>0</ixz>
            <iyy>1</iyy>
            <iyz>0</iyz>
            <izz>1</izz>
          </inertia>
        </inertial>
        <collision name='right_back_wheel_fixed_joint_lump__collision_collision'>
          <pose>0 0 0 1.57089 1.57079 -3.14159</pose>
          <geometry>
            <cylinder>
              <length>0.0127</length>
              <radius>0.02</radius>
            </cylinder>
          </geometry>
          <surface>
            <contact>
              <ode/>
            </contact>
            <bounce/>
            <friction>
              <torsional>
                <ode/>
              </torsional>
              <ode/>
            </friction>
          </surface>
          <max_contacts>10</max_contacts>
        </collision>
        <visual name='right_back_wheel_visual_visual'>
          <pose>0 0 0 1.57089 1.57079 -3.14159</pose>
          <geometry>
            <cylinder>
              <length>0.0127</length>
              <radius>0.02</radius>
            </cylinder>
          </geometry>
          <material>
            <script>
              <name>Gazebo/Black</name>
              <uri>file://media/materials/scripts/gazebo.material</uri>
            </script>
          </material>
        </visual>
        <gravity>1</gravity>
        <velocity_decay/>
        <self_collide>0</self_collide>
        <enable_wind>0</enable_wind>
        <kinematic>0</kinematic>
      </link>
      <joint name='right_front_wheel_hinge' type='revolute'>
        <pose relative_to='chassis2'>0.0381 -0.0584 0 0 -0 0</pose>
        <parent>chassis2</parent>
        <child>right_front_wheel</child>
        <axis>
          <xyz>0 1 0</xyz>
          <limit>
            <lower>-1e+16</lower>
            <upper>1e+16</upper>
          </limit>
          <dynamics>
            <spring_reference>0</spring_reference>
            <spring_stiffness>0</spring_stiffness>
          </dynamics>
        </axis>
      </joint>
      <link name='right_front_wheel'>
        <pose relative_to='right_front_wheel_hinge'>0 0 0 0 -0 0</pose>
        <inertial>
          <pose>0 0 0 -0 1.5707 1.5707</pose>
          <mass>10</mass>
          <inertia>
            <ixx>1</ixx>
            <ixy>0</ixy>
            <ixz>0</ixz>
            <iyy>1</iyy>
            <iyz>0</iyz>
            <izz>1</izz>
          </inertia>
        </inertial>
        <collision name='right_front_wheel_fixed_joint_lump__collision_collision'>
          <pose>0 0 0 1.57089 1.57079 -3.14159</pose>
          <geometry>
            <cylinder>
              <length>0.0127</length>
              <radius>0.02</radius>
            </cylinder>
          </geometry>
          <surface>
            <contact>
              <ode/>
            </contact>
            <bounce/>
            <friction>
              <torsional>
                <ode/>
              </torsional>
              <ode/>
            </friction>
          </surface>
          <max_contacts>10</max_contacts>
        </collision>
        <visual name='right_front_wheel_visual_visual'>
          <pose>0 0 0 1.57089 1.57079 -3.14159</pose>
          <geometry>
            <cylinder>
              <length>0.0127</length>
              <radius>0.02</radius>
            </cylinder>
          </geometry>
          <material>
            <script>
              <name>Gazebo/Black</name>
              <uri>file://media/materials/scripts/gazebo.material</uri>
            </script>
          </material>
        </visual>
        <gravity>1</gravity>
        <velocity_decay/>
        <self_collide>0</self_collide>
        <enable_wind>0</enable_wind>
        <kinematic>0</kinematic>
      </link>
      <static>0</static>
      <plugin name='differential_drive_controller' filename='libgazebo_ros_diff_drive.so'>
        <legacyMode>0</legacyMode>
        <alwaysOn>1</alwaysOn>
        <updateRate>20</updateRate>
        <leftJoint>left_back_wheel_hinge</leftJoint>
        <rightJoint>right_back_wheel_hinge</rightJoint>
        <wheelSeparation>0.1608</wheelSeparation>
        <wheelDiameter>0.1</wheelDiameter>
        <wheelTorque>5</wheelTorque>
        <commandTopic>robot2/cmd_vel</commandTopic>
        <odometryTopic>robot2/odom</odometryTopic>
        <odometryFrame>grid/odom</odometryFrame>
        <robotBaseFrame>chassis2</robotBaseFrame>
        <robotNamespace>/</robotNamespace>
      </plugin>
      <pose>1.4495 2.35959 0.05 0 0 -1.5708</pose>
    </model>
    <model name='myrobot4'>
      <link name='chassis4'>
        <inertial>
          <pose>0 0 0.1 0 -0 0</pose>
          <mass>10</mass>
          <inertia>
            <ixx>0.5</ixx>
            <ixy>0</ixy>
            <ixz>0</ixz>
            <iyy>1</iyy>
            <iyz>0</iyz>
            <izz>0.1</izz>
          </inertia>
        </inertial>
        <collision name='chassis4_fixed_joint_lump__collision_collision'>
          <pose>0 0 0 0 -0 0</pose>
          <geometry>
            <box>
              <size>0.1016 0.1016 0.02</size>
            </box>
          </geometry>
          <surface>
            <contact>
              <ode/>
            </contact>
            <bounce/>
            <friction>
              <torsional>
                <ode/>
              </torsional>
              <ode/>
            </friction>
          </surface>
          <max_contacts>10</max_contacts>
        </collision>
        <visual name='chassis4_visual_visual'>
          <pose>0 0 0 0 -0 0</pose>
          <geometry>
            <box>
              <size>0.1016 0.1016 0.02</size>
            </box>
          </geometry>
          <material>
            <script>
              <name>robot4/Image</name>
              <uri>file://media/materials/scripts/gazebo.material</uri>
            </script>
          </material>
        </visual>
        <gravity>1</gravity>
        <velocity_decay/>
        <self_collide>0</self_collide>
        <enable_wind>0</enable_wind>
        <kinematic>0</kinematic>
      </link>
      <joint name='left_back_wheel_hinge' type='revolute'>
        <pose relative_to='chassis4'>-0.0381 0.0584 0 0 -0 0</pose>
        <parent>chassis4</parent>
        <child>left_back_wheel</child>
        <axis>
          <xyz>0 1 0</xyz>
          <limit>
            <lower>-1e+16</lower>
            <upper>1e+16</upper>
          </limit>
          <dynamics>
            <spring_reference>0</spring_reference>
            <spring_stiffness>0</spring_stiffness>
          </dynamics>
        </axis>
      </joint>
      <link name='left_back_wheel'>
        <pose relative_to='left_back_wheel_hinge'>0 0 0 0 -0 0</pose>
        <inertial>
          <pose>0 0 0 -0 1.5707 1.5707</pose>
          <mass>5</mass>
          <inertia>
            <ixx>1</ixx>
            <ixy>0</ixy>
            <ixz>0</ixz>
            <iyy>1</iyy>
            <iyz>0</iyz>
            <izz>1</izz>
          </inertia>
        </inertial>
        <collision name='left_back_wheel_fixed_joint_lump__collision_collision'>
          <pose>0 0 0 1.57089 1.57079 -3.14159</pose>
          <geometry>
            <cylinder>
              <length>0.0127</length>
              <radius>0.02</radius>
            </cylinder>
          </geometry>
          <surface>
            <contact>
              <ode/>
            </contact>
            <bounce/>
            <friction>
              <torsional>
                <ode/>
              </torsional>
              <ode/>
            </friction>
          </surface>
          <max_contacts>10</max_contacts>
        </collision>
        <visual name='left_back_wheel_visual_visual'>
          <pose>0 0 0 1.57089 1.57079 -3.14159</pose>
          <geometry>
            <cylinder>
              <length>0.0127</length>
              <radius>0.02</radius>
            </cylinder>
          </geometry>
          <material>
            <script>
              <name>Gazebo/Black</name>
              <uri>file://media/materials/scripts/gazebo.material</uri>
            </script>
          </material>
        </visual>
        <gravity>1</gravity>
        <velocity_decay/>
        <self_collide>0</self_collide>
        <enable_wind>0</enable_wind>
        <kinematic>0</kinematic>
      </link>
      <joint name='left_front_wheel_hinge' type='revolute'>
        <pose relative_to='chassis4'>0.0381 0.0584 0 0 -0 0</pose>
        <parent>chassis4</parent>
        <child>left_front_wheel</child>
        <axis>
          <xyz>0 1 0</xyz>
          <limit>
            <lower>-1e+16</lower>
            <upper>1e+16</upper>
          </limit>
          <dynamics>
            <spring_reference>0</spring_reference>
            <spring_stiffness>0</spring_stiffness>
          </dynamics>
        </axis>
      </joint>
      <link name='left_front_wheel'>
        <pose relative_to='left_front_wheel_hinge'>0 0 0 0 -0 0</pose>
        <inertial>
          <pose>0 0 0 -0 1.5707 1.5707</pose>
          <mass>5</mass>
          <inertia>
            <ixx>1</ixx>
            <ixy>0</ixy>
            <ixz>0</ixz>
            <iyy>1</iyy>
            <iyz>0</iyz>
            <izz>1</izz>
          </inertia>
        </inertial>
        <collision name='left_front_wheel_fixed_joint_lump__collision_collision'>
          <pose>0 0 0 1.57089 1.57079 -3.14159</pose>
          <geometry>
            <cylinder>
              <length>0.0127</length>
              <radius>0.02</radius>
            </cylinder>
          </geometry>
          <surface>
            <contact>
              <ode/>
            </contact>
            <bounce/>
            <friction>
              <torsional>
                <ode/>
              </torsional>
              <ode/>
            </friction>
          </surface>
          <max_contacts>10</max_contacts>
        </collision>
        <visual name='left_front_wheel_visual_visual'>
          <pose>0 0 0 1.57089 1.57079 -3.14159</pose>
          <geometry>
            <cylinder>
              <length>0.0127</length>
              <radius>0.02</radius>
            </cylinder>
          </geometry>
          <material>
            <script>
              <name>Gazebo/Black</name>
              <uri>file://media/materials/scripts/gazebo.material</uri>
            </script>
          </material>
        </visual>
        <gravity>1</gravity>
        <velocity_decay/>
        <self_collide>0</self_collide>
        <enable_wind>0</enable_wind>
        <kinematic>0</kinematic>
      </link>
      <joint name='right_back_wheel_hinge' type='revolute'>
        <pose relative_to='chassis4'>-0.0381 -0.0584 0 0 -0 0</pose>
        <parent>chassis4</parent>
        <child>right_back_wheel</child>
        <axis>
          <xyz>0 1 0</xyz>
          <limit>
            <lower>-1e+16</lower>
            <upper>1e+16</upper>
          </limit>
          <dynamics>
            <spring_reference>0</spring_reference>
            <spring_stiffness>0</spring_stiffness>
          </dynamics>
        </axis>
      </joint>
      <link name='right_back_wheel'>
        <pose relative_to='right_back_wheel_hinge'>0 0 0 0 -0 0</pose>
        <inertial>
          <pose>0 0 0 -0 1.5707 1.5707</pose>
          <mass>5</mass>
          <inertia>
            <ixx>1</ixx>
            <ixy>0</ixy>
            <ixz>0</ixz>
            <iyy>1</iyy>
            <iyz>0</iyz>
            <izz>1</izz>
          </inertia>
        </inertial>
        <collision name='right_back_wheel_fixed_joint_lump__collision_collision'>
          <pose>0 0 0 1.57089 1.57079 -3.14159</pose>
          <geometry>
            <cylinder>
              <length>0.0127</length>
              <radius>0.02</radius>
            </cylinder>
          </geometry>
          <surface>
            <contact>
              <ode/>
            </contact>
            <bounce/>
            <friction>
              <torsional>
                <ode/>
              </torsional>
              <ode/>
            </friction>
          </surface>
          <max_contacts>10</max_contacts>
        </collision>
        <visual name='right_back_wheel_visual_visual'>
          <pose>0 0 0 1.57089 1.57079 -3.14159</pose>
          <geometry>
            <cylinder>
              <length>0.0127</length>
              <radius>0.02</radius>
            </cylinder>
          </geometry>
          <material>
            <script>
              <name>Gazebo/Black</name>
              <uri>file://media/materials/scripts/gazebo.material</uri>
            </script>
          </material>
        </visual>
        <gravity>1</gravity>
        <velocity_decay/>
        <self_collide>0</self_collide>
        <enable_wind>0</enable_wind>
        <kinematic>0</kinematic>
      </link>
      <joint name='right_front_wheel_hinge' type='revolute'>
        <pose relative_to='chassis4'>0.0381 -0.0584 0 0 -0 0</pose>
        <parent>chassis4</parent>
        <child>right_front_wheel</child>
        <axis>
          <xyz>0 1 0</xyz>
          <limit>
            <lower>-1e+16</lower>
            <upper>1e+16</upper>
          </limit>
          <dynamics>
            <spring_reference>0</spring_reference>
            <spring_stiffness>0</spring_stiffness>
          </dynamics>
        </axis>
      </joint>
      <link name='right_front_wheel'>
        <pose relative_to='right_front_wheel_hinge'>0 0 0 0 -0 0</pose>
        <inertial>
          <pose>0 0 0 -0 1.5707 1.5707</pose>
          <mass>5</mass>
          <inertia>
            <ixx>1</ixx>
            <ixy>0</ixy>
            <ixz>0</ixz>
            <iyy>1</iyy>
            <iyz>0</iyz>
            <izz>1</izz>
          </inertia>
        </inertial>
        <collision name='right_front_wheel_fixed_joint_lump__collision_collision'>
          <pose>0 0 0 1.57089 1.57079 -3.14159</pose>
          <geometry>
            <cylinder>
              <length>0.0127</length>
              <radius>0.02</radius>
            </cylinder>
          </geometry>
          <surface>
            <contact>
              <ode/>
            </contact>
            <bounce/>
            <friction>
              <torsional>
                <ode/>
              </torsional>
              <ode/>
            </friction>
          </surface>
          <max_contacts>10</max_contacts>
        </collision>
        <visual name='right_front_wheel_visual_visual'>
          <pose>0 0 0 1.57089 1.57079 -3.14159</pose>
          <geometry>
            <cylinder>
              <length>0.0127</length>
              <radius>0.02</radius>
            </cylinder>
          </geometry>
          <material>
            <script>
              <name>Gazebo/Black</name>
              <uri>file://media/materials/scripts/gazebo.material</uri>
            </script>
          </material>
        </visual>
        <gravity>1</gravity>
        <velocity_decay/>
        <self_collide>0</self_collide>
        <enable_wind>0</enable_wind>
        <kinematic>0</kinematic>
      </link>
      <static>0</static>
      <plugin name='differential_drive_controller' filename='libgazebo_ros_diff_drive.so'>
        <legacyMode>0</legacyMode>
        <alwaysOn>1</alwaysOn>
        <updateRate>20</updateRate>
        <leftJoint>left_back_wheel_hinge</leftJoint>
        <rightJoint>right_back_wheel_hinge</rightJoint>
        <wheelSeparation>0.4</wheelSeparation>
        <wheelDiameter>0.1</wheelDiameter>
        <wheelTorque>5</wheelTorque>
        <commandTopic>robot4/cmd_vel</commandTopic>
        <odometryTopic>robot4/odom</odometryTopic>
        <odometryFrame>grid/odom</odometryFrame>
        <robotBaseFrame>chassis4</robotBaseFrame>
        <robotNamespace>/</robotNamespace>
      </plugin>
      <pose>1.4495 0.078812 0.05 0 -0 1.5708</pose>
    </model>
    <state world_name='grid3'>
      <sim_time>73 259000000</sim_time>
      <real_time>73 536816867</real_time>
      <wall_time>1642755813 8666243</wall_time>
      <iterations>73259</iterations>
      <model name='myrobot1'>
        <pose>0.988759 0.080376 0.025 -1e-06 -8e-06 1.56111</pose>
        <scale>1 1 1</scale>
        <link name='chassis1'>
          <pose>0.988759 0.080376 0.025 -1e-06 -8e-06 1.56111</pose>
          <velocity>-2.9e-05 6.1e-05 0.001402 -0.005863 0.000128 -0.000141</velocity>
          <acceleration>0.554664 0.459817 2.97833 1.09057 -0.247159 3.09773</acceleration>
          <wrench>5.54664 4.59816 29.7833 0 -0 0</wrench>
        </link>
        <link name='left_back_wheel'>
          <pose>0.929993 0.042843 0.025 -1e-06 0.014676 1.56111</pose>
          <velocity>4e-06 0.000116 0.00185 -0.005886 0.000184 -0.000146</velocity>
          <acceleration>0.10794 0.087099 3.63284 2.0637 -1.38635 -0.046366</acceleration>
          <wrench>1.0794 0.870994 36.3284 0 -0 0</wrench>
        </link>
        <link name='left_front_wheel'>
          <pose>0.930731 0.11904 0.025 -1e-06 0.171503 1.56111</pose>
          <velocity>-6e-06 3.4e-05 0.000669 -0.001712 -0.000287 -3.6e-05</velocity>
          <acceleration>0.093754 0.007233 2.59848 -3.13995 -1.30077 -3.07961</acceleration>
          <wrench>0.937544 0.072327 25.9848 0 -0 0</wrench>
        </link>
        <link name='right_back_wheel'>
          <pose>1.04679 0.041712 0.025 -1e-06 0.013921 1.56111</pose>
          <velocity>2e-06 0.000113 0.00126 -0.005741 0.000123 -7.8e-05</velocity>
          <acceleration>0.086737 0.099247 2.5762 2.20935 -1.44831 0.035679</acceleration>
          <wrench>0.867372 0.992473 25.762 0 -0 0</wrench>
        </link>
        <link name='right_front_wheel'>
          <pose>1.04753 0.117909 0.025 -1e-06 -0.038343 1.56111</pose>
          <velocity>0 -1.1e-05 0.001099 0.000634 2.1e-05 -0.000231</velocity>
          <acceleration>0.078904 -0.028167 2.31569 -0.044641 -1.43853 -0.11259</acceleration>
          <wrench>0.789039 -0.281667 23.1569 0 -0 0</wrench>
        </link>
      </model>
      <model name='myrobot2'>
        <pose>1.44964 2.35803 0.025 -1e-06 -1e-06 -1.58048</pose>
        <scale>1 1 1</scale>
        <link name='chassis2'>
          <pose>1.44964 2.35803 0.025 -1e-06 -1e-06 -1.58048</pose>
          <velocity>-1e-06 -2.8e-05 0.000384 0.001263 -0.000683 1.7e-05</velocity>
          <acceleration>-0.67841 0.344379 0.812451 -1.61825 0.806071 0.005685</acceleration>
          <wrench>-6.7841 3.4438 8.12451 0 -0 0</wrench>
        </link>
        <link name='left_back_wheel'>
          <pose>1.50841 2.39556 0.025 -1e-06 0.01468 -1.58048</pose>
          <velocity>-1.4e-05 -2.5e-05 0.000535 0.001256 -0.000733 1.4e-05</velocity>
          <acceleration>-0.101824 0.036588 1.08659 -2.06661 0.360854 0.004458</acceleration>
          <wrench>-1.01825 0.365884 10.8659 0 -0 0</wrench>
        </link>
        <link name='left_front_wheel'>
          <pose>1.50767 2.31936 0.025 0 0.171685 -1.58048</pose>
          <velocity>-1.5e-05 -4e-05 0.000359 0.002033 -0.000744 -2.2e-05</velocity>
          <acceleration>-0.110456 0.022193 1.27781 -0.049094 0.323542 -0.020922</acceleration>
          <wrench>-1.10456 0.221933 12.7781 0 -0 0</wrench>
        </link>
        <link name='right_back_wheel'>
          <pose>1.39161 2.39669 0.025 -1e-06 0.013908 -1.58048</pose>
          <velocity>-1.3e-05 -2.5e-05 1e-05 0.001258 -0.000667 1.3e-05</velocity>
          <acceleration>-0.116967 0.038416 0.037428 -1.92776 0.421833 0.014643</acceleration>
          <wrench>-1.16967 0.384162 0.37428 0 -0 0</wrench>
        </link>
        <link name='right_front_wheel'>
          <pose>1.39087 2.3205 0.025 -1e-06 -0.038438 -1.58048</pose>
          <velocity>-1.2e-05 8e-06 0.000192 -0.000443 -0.000597 -3e-05</velocity>
          <acceleration>-0.093256 0.067343 0.471234 0.087472 0.416492 -0.037775</acceleration>
          <wrench>-0.932559 0.673426 4.71234 0 -0 0</wrench>
        </link>
      </model>
      <model name='myrobot3'>
        <pose>0.988931 2.35932 0.025 -2e-06 -5e-06 -1.57339</pose>
        <scale>1 1 1</scale>
        <link name='chassis3'>
          <pose>0.988931 2.35932 0.025 -2e-06 -5e-06 -1.57339</pose>
          <velocity>1.4e-05 2e-06 -9e-06 -0.000348 0.000747 8e-06</velocity>
          <acceleration>-0.012558 -0.005112 -9.71417 -0.006067 -0.111471 0.009151</acceleration>
          <wrench>-0.125578 -0.051121 -97.1417 0 -0 0</wrench>
        </link>
        <link name='left_back_wheel'>
          <pose>1.04743 2.39727 0.025 -2e-06 7.6e-05 -1.57339</pose>
          <velocity>1.6e-05 2e-06 -0.000103 -0.000348 0.000748 8e-06</velocity>
          <acceleration>0.00059 -0.004751 -9.90922 -0.030102 -0.040685 0.007758</acceleration>
          <wrench>0.002952 -0.023756 -49.5461 0 -0 0</wrench>
        </link>
        <link name='left_front_wheel'>
          <pose>1.04723 2.32107 0.025 -2e-06 -0.000619 -1.57339</pose>
          <velocity>1.4e-05 4e-06 1.1e-05 -0.000209 0.000715 8e-06</velocity>
          <acceleration>-0.004222 3.5e-05 -9.46704 -0.002999 -0.211655 -0.010052</acceleration>
          <wrench>-0.021108 0.000174 -47.3352 0 -0 0</wrench>
        </link>
        <link name='right_back_wheel'>
          <pose>0.93063 2.39757 0.025 -2e-06 -3e-05 -1.57339</pose>
          <velocity>1.4e-05 3e-06 1.4e-05 -0.000348 0.000743 4e-06</velocity>
          <acceleration>-0.002214 -0.004055 -9.67818 -0.001149 -0.076801 -0.025311</acceleration>
          <wrench>-0.011072 -0.020277 -48.3909 0 -0 0</wrench>
        </link>
        <link name='right_front_wheel'>
          <pose>0.930432 2.32138 0.025 -2e-06 -0.020087 -1.57339</pose>
          <velocity>1.5e-05 2e-06 0.000113 -0.000364 0.000763 9e-06</velocity>
          <acceleration>-0.0003 -0.005397 -9.42704 1.4e-05 0.005433 0.011994</acceleration>
          <wrench>-0.001501 -0.026985 -47.1352 0 -0 0</wrench>
        </link>
      </model>
      <model name='myrobot4'>
        <pose>1.44947 0.079078 0.025 1e-06 -4e-06 1.56822</pose>
        <scale>1 1 1</scale>
        <link name='chassis4'>
          <pose>1.44947 0.079078 0.025 1e-06 -4e-06 1.56822</pose>
          <velocity>-3.7e-05 -5.1e-05 0.000226 0.004251 -0.002106 -0.000125</velocity>
          <acceleration>-0.407114 0.040055 0.377213 -0.55371 -0.746447 -0.001635</acceleration>
          <wrench>-4.07114 0.400551 3.77213 0 -0 0</wrench>
        </link>
        <link name='left_back_wheel'>
          <pose>1.39097 0.041129 0.025 1e-06 7.6e-05 1.56822</pose>
          <velocity>-4.2e-05 -5.2e-05 -5.7e-05 0.004234 -0.002107 -0.000129</velocity>
          <acceleration>-0.055089 -0.071999 0.214316 2.03525 0.373275 -3.13869</acceleration>
          <wrench>-0.275443 -0.359994 1.07158 0 -0 0</wrench>
        </link>
        <link name='left_front_wheel'>
          <pose>1.39117 0.117328 0.025 1e-06 -0.000536 1.56822</pose>
          <velocity>-3.2e-05 -6.9e-05 0.000268 0.000119 -0.002099 -0.00011</velocity>
          <acceleration>-0.060015 -0.06586 0.12627 3.13254 0.375402 -3.1321</acceleration>
          <wrench>-0.300075 -0.329302 0.631352 0 -0 0</wrench>
        </link>
        <link name='right_back_wheel'>
          <pose>1.50777 0.040828 0.025 1e-06 -2.9e-05 1.56822</pose>
          <velocity>-4.3e-05 -8.4e-05 0.000399 0.004194 -0.002119 -0.000106</velocity>
          <acceleration>-0.055948 -0.099857 0.814513 1.99487 0.388016 -3.12022</acceleration>
          <wrench>-0.279738 -0.499284 4.07256 0 -0 0</wrench>
        </link>
        <link name='right_front_wheel'>
          <pose>1.50797 0.117028 0.025 1e-06 -0.019956 1.56822</pose>
          <velocity>-3.9e-05 -4e-06 0.000111 0.00022 -0.00194 -7e-05</velocity>
          <acceleration>-0.065444 -0.028042 0.198262 -3.05735 0.246397 -3.08481</acceleration>
          <wrench>-0.327219 -0.140212 0.991311 0 -0 0</wrench>
        </link>
      </model>
      <model name='stage2'>
        <pose>1.2192 1.2192 -0.045 0 -0 1.5708</pose>
        <scale>1 1 1</scale>
        <link name='ridges'>
          <pose>1.2192 1.2192 -0.045 0 -0 0.0008</pose>
          <velocity>0 0 0 0 -0 0</velocity>
          <acceleration>0 0 0 0 -0 0</acceleration>
          <wrench>0 0 0 0 -0 0</wrench>
        </link>
      </model>
      <light name='sun'>
        <pose>0 0 10 0 -0 0</pose>
      </light>
    </state>
    <gui fullscreen='0'>
      <camera name='user_camera'>
        <pose>1.08341 1.1584 2.71025 -1e-06 1.5538 1.5682</pose>
        <view_controller>orbit</view_controller>
        <projection_type>perspective</projection_type>
      </camera>
    </gui>
  </world>
</sdf>
